Workbook

Sheet 使用说明
A1: CASHFLOW｜原生评审工作簿 · v0.6.4
A2: 状态 | B2: 原生可编辑；事实、自动化证据、待评审及待执行分开
A3: 操作 | B3: 蓝色表头可筛选；冻结标题；金额为数值单元格；不填写虚构签字
A4: 来源 | B4: 当前代码、audit/validation-latest.json、公开来源台账
A5: 批准 | B5: 待指定责任角色正式评审；本次仅复核资料和文件有效性

Sheet 职业财务摘要
A1: 职业财务摘要｜参考profile开局
A2: 公式只对应当前参考profile，教育贷款初始化兼容差异见DEC-04。
A3: 金额为数值；工资与支出图用于设计复核，不代表难度平衡已获批准。
A4: 职业 | B4: 工资 | C4: 税 | D4: 其他支出 | E4: 贷款月供 | F4: 总支出（公式） | G4: 净流入（公式） | H4: 一次性储蓄
A5: 教师 | B5: 3300 | C5: 630 | D5: 760 | E5: 740 | F5: =C5+D5+E5 -> 2130 | G5: =B5-F5 -> 1170 | H5: 400
A6: 护士 | B6: 3100 | C6: 600 | D6: 710 | E6: 640 | F6: =C6+D6+E6 -> 1950 | G6: =B6-F6 -> 1150 | H6: 480
A7: 警察 | B7: 3000 | C7: 580 | D7: 690 | E7: 610 | F7: =C7+D7+E7 -> 1880 | G7: =B7-F7 -> 1120 | H7: 520
A8: 机械师 | B8: 2000 | C8: 360 | D8: 450 | E8: 470 | F8: =C8+D8+E8 -> 1280 | G8: =B8-F8 -> 720 | H8: 670
A9: 卡车司机 | B9: 2500 | C9: 460 | D9: 570 | E9: 590 | F9: =C9+D9+E9 -> 1620 | G9: =B9-F9 -> 880 | H9: 750
A10: 秘书 | B10: 2500 | C10: 460 | D10: 570 | E10: 590 | F10: =C10+D10+E10 -> 1620 | G10: =B10-F10 -> 880 | H10: 710
A11: 工程师 | B11: 4900 | C11: 1050 | D11: 1090 | E11: 1010 | F11: =C11+D11+E11 -> 3150 | G11: =B11-F11 -> 1750 | H11: 400
A12: 律师 | B12: 7500 | C12: 1830 | D12: 1650 | E12: 1550 | F12: =C12+D12+E12 -> 5030 | G12: =B12-F12 -> 2470 | H12: 400
A13: 医生 | B13: 13200 | C13: 3420 | D13: 2880 | E13: 2600 | F13: =C13+D13+E13 -> 8900 | G13: =B13-F13 -> 4300 | H13: 400
A14: 航空驾驶员 | B14: 9500 | C14: 2350 | D14: 2210 | E14: 2340 | F14: =C14+D14+E14 -> 6900 | G14: =B14-F14 -> 2600 | H14: 400
A15: 企业经理 | B15: 4600 | C15: 910 | D15: 1000 | E15: 960 | F15: =C15+D15+E15 -> 2870 | G15: =B15-F15 -> 1730 | H15: 400
A16: 清洁工 | B16: 1600 | C16: 280 | D16: 300 | E16: 370 | F16: =C16+D16+E16 -> 950 | G16: =B16-F16 -> 650 | H16: 560

Sheet 需求清单
A1: 需求规则与数值主表
A2: 基线 v0.6.4 | 2026-10-27 | 自动化通过不代替最终验收
A3: 请使用筛选定位ID；字段名称保留实现含义，来源与状态不得删除。
A4: 需求ID | B4: 主题 | C4: 通过标准 | D4: 负责角色 | E4: 测试／依据 | F4: UAT | G4: 状态
A5: REQ-001 | B5: 完整包本地入口 | C5: 解压完整包后打开index；无外部资源／接口仍可建房、开局、保存和恢复。 | D5: 前端／构建 | E5: scripts/standalone-smoke.cjs | F5: UAT-01 | G5: 真实file入口仍待设备实测
A6: REQ-002 | B6: 规则与财务 | C6: 现金、资产、债务、月供与现金流按选定profile结算，不混用实体与在线版。 | D6: 规则／数值 | E6: engine.test.cjs | F6: UAT-02 | G6: 机械测试通过，参考差异未关闭
A7: REQ-003 | B7: 完整轮次 | C7: 逐人选梦想、掷骰、待处理事件、结束回合与终局的先后关系正确。 | D7: 规则／前端 | E7: scripts/reference-ui-smoke.cjs | F7: UAT-02 | G7: 有自动化证据，待用户验收
A8: REQ-004 | B8: 显示与金额 | C8: 中文标签、份数与最大允许交易金额不重叠；报表开合不写回旧布局。 | D8: UI／前端 | E8: scripts/attachment-regressions-smoke.cjs | F8: UAT-03 | G8: 1x/2x局部验证通过
A9: REQ-005 | B9: 在线权威结算 | C9: 非当前座位不能发游戏动作；过期version被拒绝；客户端不接收未来牌序。 | D9: 后端 | E9: rooms.test.cjs | F9: UAT-07 | G9: 有自动化证据
A10: REQ-006 | B10: 持久化与恢复 | C10: 刷新／短暂断网恢复会话；未确认交易不被当作已完成。 | D10: 前后端 | E10: scripts/online-smoke.cjs | F10: UAT-06 | G10: 跨版本迁移矩阵待补
A11: REQ-007 | B11: 无遮挡查看棋盘 | C11: B或查看棋盘暂收卡片、报表、聊天；返回保留输入；R/E不结算。 | D11: 前端 | E11: scripts/attachment-regressions-smoke.cjs | F11: UAT-05 | G11: 有自动化证据
A12: REQ-008 | B12: 参考来源可追溯 | C12: 原素材、规则观察和推断分别记录；不能把模板坐标当作所有运行分支已验证。 | D12: 策划／QA | E12: audit/dice-layout-fixtures.json | F12: UAT-08 | G12: 多骰运行位置待核验
A13: REQ-009 | B13: 受测包可定位 | C13: 版本、代码提交、入口HTML及ZIP SHA与测试证据关联。 | D13: 发布／QA | E13: audit/validation-latest.json | F13: UAT-01 | G13: 当前快照有记录
A14: REQ-010 | B14: 原版一致性范围 | C14: 版次、全部文案／规则／状态均有对照依据后才可宣布原版完全一致。 | D14: 产品／规则审阅 | E14: audit/reference-coverage.json | F14: UAT-08 | G14: 阻断：原版全等未成立
A15: REQ-011 | B15: 股票与借还子状态 | C15: 取消不扣款；不足现金走差额贷款；返回后的份数与债务选择符合规则。 | D15: 规则／前端 | E15: scripts/reference-ui-smoke.cjs | F15: UAT-03 | G15: 有局部自动化证据
... A22: REQ-018 | B22: 用户验收闭环 | C22: 指定候选包与设备，逐场景记录实测、缺陷、遗留项和签收。 | D22: 产品／用户／QA | E22: audit/validation-latest.json | F22: UAT-08 | G22: 尚无正式最终签收

Sheet 规则决策
A1: 需求规则与数值主表
A2: 基线 v0.6.4 | 2026-10-27 | 自动化通过不代替最终验收
A3: 请使用筛选定位ID；字段名称保留实现含义，来源与状态不得删除。
A4: ID | B4: 主题 | C4: 当前事实 | D4: 处理要求 | E4: 责任角色 | F4: 状态
A5: DEC-01 | B5: 参考版次 | C5: 官网经典在线版与实体101不可默认等同 | D5: 确认最终比较版本和合法使用边界 | E5: 产品／策划 | F5: 待确认
A6: DEC-02 | B6: 黄金结算 | C6: 官网观察600；当前按10×600=6000 | D6: 选择复现网站行为或卡面计算 | E6: 规则审阅／产品 | F6: 待确认
A7: DEC-03 | B7: 语言与视觉 | C7: 当前中文、参考站英文 | D7: 分开确认文案、布局、像素与字体目标 | E7: UX／产品 | F7: 待确认
A8: DEC-04 | B8: 教育贷款 | C8: 参考profile初始化省略school债务 | D8: 确认兼容范围，保留旧profile区别 | E8: 规则审阅 | F8: 待核验
A9: DEC-05 | B9: 多骰位置 | C9: 原图与单骰模板锚点已核对，多骰居中属实现选择 | D9: 补充不同页面的原站运行坐标证据 | E9: UX／QA | F9: 待核验
A10: DEC-06 | B10: 真实文件入口 | C10: 内嵌index已在HTTP离线路径验证，环境阻止file自动化 | D10: Windows/Edge及Chrome真实双击并记录SHA | E10: QA／用户 | F10: 待执行
A11: DEC-07 | B11: 性能目标 | C11: 单进程Node，rooms上限200不是容量结果 | D11: 确定并发、响应延迟、存档写入预算 | E11: 技术负责人 | F11: 待评审
A12: DEC-08 | B12: 最终签收 | C12: 已有353单测、27浏览器检查；无正式UAT批准 | D12: 产品、规则审阅与用户签收具体候选包 | E12: 产品／用户 | F12: 待执行
A13: DEC-09 | B13: 快车道发薪口径 | C13: 当前参考profile发薪包含内圈salary − ratExpenses；报表收入仅fastBase + fastGain | D13: 对照原版实际发薪，确认目标口径后再决定是否改规则 | E13: 规则审阅／产品 | F13: 待核验

Sheet 职业数据
A1: 需求规则与数值主表
A2: 基线 v0.6.4 | 2026-10-27 | 自动化通过不代替最终验收
A3: 请使用筛选定位ID；字段名称保留实现含义，来源与状态不得删除。
A4: 记录序号 | B4: id | C4: name | D4: english | E4: salary | F4: tax | G4: homePayment | H4: schoolPayment | I4: carPayment | J4: creditPayment | K4: retailPayment | L4: other | M4: savings | N4: childCost | O4: homeDebt | P4: schoolDebt | Q4: carDebt | R4: creditDebt | S4: retailDebt
A5: 0 | B5: 0 | C5: 教师 | D5: Teacher (K-12) | E5: 3300 | F5: 630 | G5: 500 | H5: 60 | I5: 100 | J5: 90 | K5: 50 | L5: 760 | M5: 400 | N5: 180 | O5: 50000 | P5: 12000 | Q5: 5000 | R5: 3000 | S5: 1000
A6: 1 | B6: 1 | C6: 护士 | D6: Nurse | E6: 3100 | F6: 600 | G6: 400 | H6: 30 | I6: 100 | J6: 90 | K6: 50 | L6: 710 | M6: 480 | N6: 170 | O6: 47000 | P6: 6000 | Q6: 5000 | R6: 3000 | S6: 1000
A7: 2 | B7: 2 | C7: 警察 | D7: Police Officer | E7: 3000 | F7: 580 | G7: 400 | H7: 0 | I7: 100 | J7: 60 | K7: 50 | L7: 690 | M7: 520 | N7: 160 | O7: 46000 | P7: 0 | Q7: 5000 | R7: 2000 | S7: 1000
A8: 3 | B8: 3 | C8: 机械师 | D8: Mechanic | E8: 2000 | F8: 360 | G8: 300 | H8: 0 | I8: 60 | J8: 60 | K8: 50 | L8: 450 | M8: 670 | N8: 110 | O8: 31000 | P8: 0 | Q8: 3000 | R8: 2000 | S8: 1000
A9: 4 | B9: 4 | C9: 卡车司机 | D9: Truck Driver | E9: 2500 | F9: 460 | G9: 400 | H9: 0 | I9: 80 | J9: 60 | K9: 50 | L9: 570 | M9: 750 | N9: 140 | O9: 38000 | P9: 0 | Q9: 4000 | R9: 2000 | S9: 1000
A10: 5 | B10: 5 | C10: 秘书 | D10: Secretary | E10: 2500 | F10: 460 | G10: 400 | H10: 0 | I10: 80 | J10: 60 | K10: 50 | L10: 570 | M10: 710 | N10: 140 | O10: 38000 | P10: 0 | Q10: 4000 | R10: 2000 | S10: 1000
A11: 6 | B11: 6 | C11: 工程师 | D11: Engineer | E11: 4900 | F11: 1050 | G11: 700 | H11: 60 | I11: 140 | J11: 120 | K11: 50 | L11: 1090 | M11: 400 | N11: 250 | O11: 75000 | P11: 12000 | Q11: 7000 | R11: 4000 | S11: 1000
A12: 7 | B12: 7 | C12: 律师 | D12: Lawyer | E12: 7500 | F12: 1830 | G12: 1100 | H12: 390 | I12: 220 | J12: 180 | K12: 50 | L12: 1650 | M12: 400 | N12: 380 | O12: 115000 | P12: 78000 | Q12: 11000 | R12: 6000 | S12: 1000
A13: 8 | B13: 8 | C13: 医生 | D13: Doctor (MD) | E13: 13200 | F13: 3420 | G13: 1900 | H13: 750 | I13: 380 | J13: 270 | K13: 50 | L13: 2880 | M13: 400 | N13: 640 | O13: 202000 | P13: 150000 | Q13: 19000 | R13: 9000 | S13: 1000
A14: 9 | B14: 9 | C14: 航空驾驶员 | D14: Airline Pilot | E14: 9500 | F14: 2350 | G14: 1330 | H14: 0 | I14: 300 | J14: 660 | K14: 50 | L14: 2210 | M14: 400 | N14: 480 | O14: 143000 | P14: 0 | Q14: 15000 | R14: 22000 | S14: 1000
A15: 10 | B15: 10 | C15: 企业经理 | D15: Business Manager | E15: 4600 | F15: 910 | G15: 700 | H15: 60 | I15: 120 | J15: 90 | K15: 50 | L15: 1000 | M15: 400 | N15: 240 | O15: 75000 | P15: 12000 | Q15: 6000 | R15: 3000 | S15: 1000
A16: 11 | B16: 11 | C16: 清洁工 | D16: Janitor | E16: 1600 | F16: 280 | G16: 200 | H16: 0 | I16: 60 | J16: 60 | K16: 50 | L16: 300 | M16: 560 | N16: 70 | O16: 20000 | P16: 0 | Q16: 4000 | R16: 2000 | S16: 1000

Sheet 小买卖
A1: 需求规则与数值主表
A2: 基线 v0.6.4 | 2026-10-27 | 自动化通过不代替最终验收
A3: 请使用筛选定位ID；字段名称保留实现含义，来源与状态不得删除。
A4: 记录序号 | B4: sourceId | C4: anyoneBuy | D4: name | E4: key | F4: type | G4: units | H4: symbol | I4: price | J4: dividend | K4: rangeMin | L4: rangeMax | M4: down | N4: value | O4: debt | P4: income | Q4: factor
A5: 0 | B5: small.0 | C5: =TRUE() -> 1 | D5: 银行存单 | E5: CD | F5: stock | G5: 1 | H5: CD | I5: 4000 | J5: 20 | K5: 4000 | L5: 4000
A6: 1 | B6: small.1 | C6: =TRUE() -> 1 | D6: 银行存单 | E6: CD | F6: stock | G6: 1 | H6: CD | I6: 5000 | J6: 20 | K6: 5000 | L6: 5000
A7: 2 | B7: small.2 | C7: =TRUE() -> 1 | D7: 2BIG 电力优先股 | E7: 2BIG | F7: stock | G7: 1 | H7: 2BIG | I7: 1200 | J7: 10 | K7: 1200 | L7: 1200
A8: 3 | B8: small.3 | C8: =TRUE() -> 1 | D8: 2BIG 电力优先股 | E8: 2BIG | F8: stock | G8: 1 | H8: 2BIG | I8: 1200 | J8: 10 | K8: 1200 | L8: 1200
A9: 4 | B9: small.4 | C9: =FALSE() -> 0 | D9: 零件创业公司 | E9: widget | F9: business | G9: 1 | M9: 3000 | N9: 3000 | O9: 0 | P9: 0
A10: 5 | B10: small.5 | C10: =FALSE() -> 0 | D10: 软件创业公司 | E10: software | F10: business | G10: 1 | M10: 5000 | N10: 5000 | O10: 0 | P10: 0
A11: 6 | B11: small.6 | C11: =FALSE() -> 0 | D11: OK4U 制药公司 | E11: OK4U | F11: split | G11: 1 | Q11: 2
A12: 7 | B12: small.7 | C12: =FALSE() -> 0 | D12: OK4U 制药公司 | E12: OK4U | F12: split | G12: 1 | Q12: 0.5
A13: 8 | B13: small.8 | C13: =FALSE() -> 0 | D13: MYT4U 电子公司 | E13: MYT4U | F13: split | G13: 1 | Q13: 2
A14: 9 | B14: small.9 | C14: =FALSE() -> 0 | D14: MYT4U 电子公司 | E14: MYT4U | F14: split | G14: 1 | Q14: 0.5
A15: 10 | B15: small.10 | C15: =FALSE() -> 0 | D15: ON2U 娱乐公司 | E15: ON2U | F15: stock | G15: 1 | H15: ON2U | I15: 20 | J15: 0 | K15: 10 | L15: 40
A16: 11 | B16: small.11 | C16: =FALSE() -> 0 | D16: ON2U 娱乐公司 | E16: ON2U | F16: stock | G16: 1 | H16: ON2U | I16: 5 | J16: 0 | K16: 10 | L16: 30
A17: 12 | B17: small.12 | C17: =FALSE() -> 0 | D17: ON2U 娱乐公司 | E17: ON2U | F17: stock | G17: 1 | H17: ON2U | I17: 40 | J17: 0 | K17: 10 | L17: 30
A18: 13 | B18: small.13 | C18: =FALSE() -> 0 | D18: ON2U 娱乐公司 | E18: ON2U | F18: stock | G18: 1 | H18: ON2U | I18: 10 | J18: 0 | K18: 10 | L18: 30
A19: 14 | B19: small.14 | C19: =FALSE() -> 0 | D19: ON2U 娱乐公司 | E19: ON2U | F19: stock | G19: 1 | H19: ON2U | I19: 20 | J19: 0 | K19: 10 | L19: 30
A20: 15 | B20: small.15 | C20: =FALSE() -> 0 | D20: ON2U 娱乐公司 | E20: ON2U | F20: stock | G20: 1 | H20: ON2U | I20: 30 | J20: 0 | K20: 10 | L20: 30
A21: 16 | B21: small.16 | C21: =FALSE() -> 0 | D21: ON2U 娱乐公司 | E21: ON2U | F21: stock | G21: 1 | H21: ON2U | I21: 10 | J21: 0 | K21: 10 | L21: 30
A22: 17 | B22: small.17 | C22: =FALSE() -> 0 | D22: ON2U 娱乐公司 | E22: ON2U | F22: stock | G22: 1 | H22: ON2U | I22: 30 | J22: 0 | K22: 10 | L22: 30
A23: 18 | B23: small.18 | C23: =FALSE() -> 0 | D23: OK4U 制药公司 | E23: OK4U | F23: stock | G23: 1 | H23: OK4U | I23: 50 | J23: 0 | K23: 5 | L23: 40
A24: 19 | B24: small.19 | C24: =FALSE() -> 0 | D24: OK4U 制药公司 | E24: OK4U | F24: stock | G24: 1 | H24: OK4U | I24: 40 | J24: 0 | K24: 5 | L24: 40
A25: 20 | B25: small.20 | C25: =FALSE() -> 0 | D25: OK4U 制药公司 | E25: OK4U | F25: stock | G25: 1 | H25: OK4U | I25: 40 | J25: 0 | K25: 5 | L25: 40
A26: 21 | B26: small.21 | C26: =FALSE() -> 0 | D26: OK4U 制药公司 | E26: OK4U | F26: stock | G26: 1 | H26: OK4U | I26: 30 | J26: 0 | K26: 5 | L26: 40
... A43: 38 | B43: small.38 | C43: =FALSE() -> 0 | D43: GRO4US 共同基金 | E43: GRO4US | F43: stock | G43: 1 | H43: GRO4US | I43: 10 | J43: 0 | K43: 10 | L43: 30
A44: 39 | B44: small.39 | C44: =FALSE() -> 0 | D44: 亲属借款 | E44: misc | F44: collectible | G44: 1 | M44: 5000 | N44: 5000 | O44: 0 | P44: 0
A45: 40 | B45: small.40 | C45: =FALSE() -> 0 | D45: 10 英亩土地 | E45: 10ACRES | F45: collectible | G45: 1 | M45: 5000 | N45: 5000 | O45: 0 | P45: 0
A46: 41 | B46: small.41 | C46: =FALSE() -> 0 | D46: 10 枚金币 | E46: gold | F46: collectible | G46: 10 | M46: 3000 | N46: 3000 | O46: 0 | P46: 0
A47: 42 | B47: small.42 | C47: =FALSE() -> 0 | D47: 稀有金币 | E47: coin | F47: collectible | G47: 8 | M47: 500 | N47: 500 | O47: 0 | P47: 0
A48: 43 | B48: small.43 | C48: =FALSE() -> 0 | D48: 三卧室两卫住宅 | E48: 3/2HOUSE | F48: property | G48: 1 | M48: 2000 | N48: 45000 | O48: 43000 | P48: 250
A49: 44 | B49: small.44 | C49: =FALSE() -> 0 | D49: 三卧室两卫住宅 | E49: 3/2HOUSE | F49: property | G49: 1 | M49: 2000 | N49: 35000 | O49: 33000 | P49: 220
A50: 45 | B50: small.45 | C50: =FALSE() -> 0 | D50: 两卧室一卫公寓 | E50: 2/1CONDO | F50: property | G50: 1 | M50: 5000 | N50: 40000 | O50: 35000 | P50: 220
A51: 46 | B51: small.46 | C51: =FALSE() -> 0 | D51: 两卧室一卫公寓 | E51: 2/1CONDO | F51: property | G51: 1 | M51: 5000 | N51: 55000 | O51: 50000 | P51: 160
A52: 47 | B52: small.47 | C52: =FALSE() -> 0 | D52: 两卧室一卫公寓 | E52: 2/1CONDO | F52: property | G52: 1 | M52: 4000 | N52: 40000 | O52: 36000 | P52: 140
A53: 48 | B53: small.48 | C53: =FALSE() -> 0 | D53: 两卧室一卫公寓 | E53: 2/1CONDO | F53: property | G53: 1 | M53: 5000 | N53: 50000 | O53: 45000 | P53: 100
A54: 49 | B54: small.49 | C54: =FALSE() -> 0 | D54: 两卧室一卫公寓 | E54: 2/1CONDO | F54: property | G54: 1 | M54: 5000 | N54: 60000 | O54: 55000 | P54: -100
A55: 50 | B55: small.50 | C55: =FALSE() -> 0 | D55: 三卧室两卫住宅 | E55: 3/2HOUSE | F55: property | G55: 1 | M55: 4000 | N55: 50000 | O55: 46000 | P55: 200
... A59: 54 | B59: small.54 | C59: =FALSE() -> 0 | D59: 三卧室两卫住宅 | E59: 3/2HOUSE | F59: property | G59: 1 | M59: 0 | N59: 50000 | O59: 50000 | P59: -100

Sheet 大买卖
A1: 需求规则与数值主表
A2: 基线 v0.6.4 | 2026-10-27 | 自动化通过不代替最终验收
A3: 请使用筛选定位ID；字段名称保留实现含义，来源与状态不得删除。
A4: 记录序号 | B4: sourceId | C4: anyoneBuy | D4: name | E4: key | F4: type | G4: units | H4: down | I4: value | J4: debt | K4: income
A5: 0 | B5: big.0 | C5: =FALSE() -> 0 | D5: 有限合伙投资 | E5: PARTNER | F5: business | G5: 1 | H5: 30000 | I5: 30000 | J5: 0 | K5: 1500
A6: 1 | B6: big.1 | C6: =FALSE() -> 0 | D6: 有限合伙投资 | E6: PARTNER | F6: business | G6: 1 | H6: 30000 | I6: 30000 | J6: 0 | K6: 1000
A7: 2 | B7: big.2 | C7: =FALSE() -> 0 | D7: 有限合伙投资 | E7: PARTNER | F7: business | G7: 1 | H7: 25000 | I7: 25000 | J7: 0 | K7: 1000
A8: 3 | B8: big.3 | C8: =FALSE() -> 0 | D8: 有限合伙投资 | E8: PARTNER | F8: business | G8: 1 | H8: 20000 | I8: 20000 | J8: 0 | K8: 800
A9: 4 | B9: big.4 | C9: =FALSE() -> 0 | D9: 公用电话业务 | E9: PHONE | F9: business | G9: 1 | H9: 40000 | I9: 200000 | J9: 160000 | K9: 2700
A10: 5 | B10: big.5 | C10: =FALSE() -> 0 | D10: 自助洗衣店 | E10: LAUNDRY | F10: business | G10: 1 | H10: 30000 | I10: 150000 | J10: 120000 | K10: 2500
A11: 6 | B11: big.6 | C11: =FALSE() -> 0 | D11: 洗车业务 | E11: CARWASH | F11: business | G11: 1 | H11: 25000 | I11: 125000 | J11: 100000 | K11: 1800
A12: 7 | B12: big.7 | C12: =FALSE() -> 0 | D12: 游戏厅 | E12: ARCADE | F12: business | G12: 1 | H12: 20000 | I12: 100000 | J12: 80000 | K12: 1600
A13: 8 | B13: big.8 | C13: =FALSE() -> 0 | D13: 披萨店 | E13: PIZZA | F13: business | G13: 1 | H13: 100000 | I13: 500000 | J13: 400000 | K13: 5000
A14: 9 | B14: big.9 | C14: =FALSE() -> 0 | D14: 洗车业务 | E14: CARWASH | F14: business | G14: 1 | H14: 50000 | I14: 350000 | J14: 300000 | K14: 1500
A15: 10 | B15: big.10 | C15: =FALSE() -> 0 | D15: 民宿 | E15: BED | F15: business | G15: 1 | H15: 30000 | I15: 150000 | J15: 120000 | K15: 1000
A16: 11 | B16: big.11 | C16: =FALSE() -> 0 | D16: 购物中心股份 | E16: MALL | F16: business | G16: 1 | H16: 50000 | I16: 50000 | J16: 0 | K16: 800
... A44: 39 | B44: big.39 | C44: =FALSE() -> 0 | D44: 多户出租住宅 | E44: PLEX | F44: property | G44: 8 | H44: 40000 | I44: 240000 | J44: 200000 | K44: 950

Sheet 市场
A1: 需求规则与数值主表
A2: 基线 v0.6.4 | 2026-10-27 | 自动化通过不代替最终验收
A3: 请使用筛选定位ID；字段名称保留实现含义，来源与状态不得删除。
A4: 记录序号 | B4: sourceId | C4: mode | D4: global | E4: key | F4: amount | G4: minUnits
A5: 0 | B5: market.0 | C5: sell | D5: =TRUE() -> 1 | E5: 2/1CONDO | F5: 65000 | G5: 1
A6: 1 | B6: market.1 | C6: sell | D6: =TRUE() -> 1 | E6: 2/1CONDO | F6: 55000 | G6: 1
A7: 2 | B7: market.2 | C7: sell | D7: =TRUE() -> 1 | E7: 2/1CONDO | F7: 55000 | G7: 1
A8: 3 | B8: market.3 | C8: sell | D8: =TRUE() -> 1 | E8: 2/1CONDO | F8: 45000 | G8: 1
A9: 4 | B9: market.4 | C9: sell | D9: =TRUE() -> 1 | E9: 3/2HOUSE | F9: 135000 | G9: 1
A10: 5 | B10: market.5 | C10: sell | D10: =TRUE() -> 1 | E10: 3/2HOUSE | F10: 135000 | G10: 1
A11: 6 | B11: market.6 | C11: sell | D11: =TRUE() -> 1 | E11: 3/2HOUSE | F11: 110000 | G11: 1
A12: 7 | B12: market.7 | C12: sell | D12: =TRUE() -> 1 | E12: 3/2HOUSE | F12: 100000 | G12: 1
A13: 8 | B13: market.8 | C13: sell | D13: =TRUE() -> 1 | E13: 3/2HOUSE | F13: 100000 | G13: 1
A14: 9 | B14: market.9 | C14: sell | D14: =TRUE() -> 1 | E14: 3/2HOUSE | F14: 90000 | G14: 1
A15: 10 | B15: market.10 | C15: sell | D15: =TRUE() -> 1 | E15: 3/2HOUSE | F15: 65000 | G15: 1
A16: 11 | B16: market.11 | C16: sell | D16: =TRUE() -> 1 | E16: PLEX | F16: 40000 | G16: 1
... A31: 26 | B31: market.26 | C31: startup | D31: =TRUE() -> 1 | E31: 400 | F31: 0 | G31: 1
A32: 27 | B32: market.27 | C32: lose | D32: =FALSE() -> 0 | E32: 3/2HOUSE | F32: 0 | G32: 1
A33: 28 | B33: market.28 | C33: selladd | D33: =FALSE() -> 0 | E33: 3/2HOUSE | F33: 50000 | G33: 1
A34: 29 | B34: market.29 | C34: sellmultiply | D34: =TRUE() -> 1 | E34: PARTNER | F34: 3 | G34: 1
A35: 30 | B35: market.30 | C35: sellmultiply | D35: =TRUE() -> 1 | E35: PARTNER | F35: 2 | G35: 1
A36: 31 | B36: market.31 | C36: sellmultiply | D36: =TRUE() -> 1 | E36: PARTNER | F36: 2 | G36: 1
A37: 32 | B37: market.32 | C37: fee | D37: =FALSE() -> 0 | E37: rental | F37: 500 | G37: 1
A38: 33 | B38: market.33 | C38: fee | D38: =FALSE() -> 0 | E38: rental | F38: 1000 | G38: 1
A39: 34 | B39: market.34 | C39: fee | D39: =FALSE() -> 0 | E39: 8PLEX | F39: 2000 | G39: 1
A40: 35 | B40: market.35 | C40: sell | D40: =TRUE() -> 1 | E40: coin | F40: 5000 | G40: 1
A41: 36 | B41: market.36 | C41: sell | D41: =TRUE() -> 1 | E41: gold | F41: 600 | G41: 1
A42: 37 | B42: market.37 | C42: sell | D42: =TRUE() -> 1 | E42: widget | F42: 50000 | G42: 1
A43: 38 | B43: market.38 | C43: sell | D43: =TRUE() -> 1 | E43: software | F43: 100000 | G43: 1
A44: 39 | B44: market.39 | C44: sell | D44: =TRUE() -> 1 | E44: BED | F44: 250000 | G44: 1
A45: 40 | B45: market.40 | C45: sell | D45: =TRUE() -> 1 | E45: CARWASH | F45: 250000 | G45: 1
A46: 41 | B46: market.41 | C46: sell | D46: =TRUE() -> 1 | E46: MALL | F46: 100000 | G46: 1
A47: 42 | B47: market.42 | C47: sell | D47: =TRUE() -> 1 | E47: 10ACRES | F47: 150000 | G47: 1
A48: 43 | B48: market.43 | C48: sell | D48: =TRUE() -> 1 | E48: 20ACRES | F48: 200000 | G48: 1
A49: 44 | B49: market.44 | C49: brother | D49: =FALSE() -> 0 | E49: 3/2HOUSE | F49: 500 | G49: 1

Sheet 额外支出
A1: 需求规则与数值主表
A2: 基线 v0.6.4 | 2026-10-27 | 自动化通过不代替最终验收
A3: 请使用筛选定位ID；字段名称保留实现含义，来源与状态不得删除。
A4: 记录序号 | B4: sourceId | C4: name | D4: cost | E4: child | F4: payment
A5: 0 | B5: doodad.0 | C5: 朋友聚餐 | D5: 40 | F5: 0
A6: 1 | B6: doodad.1 | C6: 赌场消费 | D6: 200 | F6: 0
A7: 2 | B7: doodad.2 | C7: 税务审计 | D7: 350 | F7: 0
A8: 3 | B8: doodad.3 | C8: 粉刷住宅 | D8: 600 | F8: 0
A9: 4 | B9: doodad.4 | C9: 购买音响 | D9: 500 | F9: 0
A10: 5 | B10: doodad.5 | C10: 购买手机 | D10: 100 | F10: 0
A11: 6 | B11: doodad.6 | C11: 购买音乐唱片 | D11: 100 | F11: 0
A12: 7 | B12: doodad.7 | C12: 请朋友喝咖啡 | D12: 10 | F12: 0
A13: 8 | B13: doodad.8 | C13: 打两轮高尔夫 | D13: 100 | F13: 0
A14: 9 | B14: doodad.9 | C14: 观看球赛 | D14: 50 | F14: 0
A15: 10 | B15: doodad.10 | C15: 购买手表 | D15: 150 | F15: 0
A16: 11 | B16: doodad.11 | C16: 购买保龄球 | D16: 80 | F16: 0
... A39: 34 | B39: doodad.34 | C39: 更换热水器 | D39: 450 | F39: 0
A40: 35 | B40: doodad.35 | C40: 子女大学学费 | D40: 1500 | E40: has | F40: 0
A41: 36 | B41: doodad.36 | C41: 子女生日派对 | D41: 100 | E41: has | F41: 0
A42: 37 | B42: doodad.37 | C42: 子女牙齿矫正 | D42: 2000 | E42: has | F42: 0
A43: 38 | B43: doodad.38 | C43: 女儿婚礼 | D43: 2000 | E43: has | F43: 0
A44: 39 | B44: doodad.39 | C44: 购买儿童玩具 | D44: 50 | E44: per | F44: 0
A45: 40 | B45: doodad.40 | C45: 购买大屏电视 | D45: 4000 | F45: 120
A46: 41 | B46: doodad.41 | C46: 购买新游艇 | D46: 18000 | F46: 340

Sheet 梦想
A1: 需求规则与数值主表
A2: 基线 v0.6.4 | 2026-10-27 | 自动化通过不代替最终验收
A3: 请使用筛选定位ID；字段名称保留实现含义，来源与状态不得删除。
A4: 记录序号 | B4: name | C4: cost | D4: position | E4: icon | F4: artKey
A5: 0 | B5: 儿童投资学校 | C5: 125000 | D5: 0 | E5: ☆ | F5: stock_market_for_kids
A6: 1 | B6: 帆船比赛 | C6: 150000 | D6: 3 | E6: ☆ | F6: yacht_racing
A7: 2 | B7: 戛纳电影节 | C7: 125000 | D7: 6 | E7: ☆ | F7: cannes_film_festival
A8: 3 | B8: 蒙大拿湖畔钓鱼小屋 | C8: 100000 | D8: 8 | E8: ☆ | F8: private_fishing_cabin_on_a_montana_lake
A9: 4 | B9: 以你命名的公园 | C9: 225000 | D9: 10 | E9: ☆ | F9: park_named_after_you
A10: 5 | B10: 竞选市长 | C10: 125000 | D10: 12 | E10: ☆ | F10: run_for_mayor
A11: 6 | B11: 支持信仰事业 | C11: 175000 | D11: 14 | E11: ☆ | F11: gift_of_faith
A12: 7 | B12: 阿尔卑斯直升机滑雪 | C12: 150000 | D12: 16 | E12: ☆ | F12: heli_ski_the_swiss_alps
A13: 8 | B13: 与总统共进晚餐 | C13: 100000 | D13: 18 | E13: ☆ | F13: dinner_with_the_president
A14: 9 | B14: 癌症与艾滋病研究中心 | C14: 225000 | D14: 20 | E14: ☆ | F14: research_center_for_cancer_and_aids
A15: 10 | B15: 游览世界七大奇迹 | C15: 200000 | D15: 22 | E15: ☆ | F15: 7_wonders_of_the_world
A16: 11 | B16: 保护海洋哺乳动物 | C16: 125000 | D16: 24 | E16: ☆ | F16: save_the_ocean_mammals
... A27: 22 | B27: 亚洲古城之旅 | C27: 150000 | D27: 46 | E27: ☆ | F27: ancient_asian_cities

Sheet 快车道
A1: 需求规则与数值主表
A2: 基线 v0.6.4 | 2026-10-27 | 自动化通过不代替最终验收
A3: 请使用筛选定位ID；字段名称保留实现含义，来源与状态不得删除。
A4: 记录序号 | B4: type | C4: name | D4: cost | E4: income | F4: rollmin | G4: reward | H4: artKey
A5: 0 | B5: dream | C5: 儿童投资学校 | D5: 125000 | E5: 0 | F5: 0 | G5: 0 | H5: stock_market_for_kids
A6: 1 | B6: charity | C6: 慈善
A7: 2 | B7: business | C7: 暖通空调服务 | D7: 200000 | E7: 10000 | F7: 0 | G7: 0 | H7: heat_and_a_c_service
A8: 3 | B8: dream | C8: 帆船比赛 | D8: 150000 | E8: 0 | F8: 0 | G8: 0 | H8: yacht_racing
A9: 4 | B9: business | C9: 卡车配件工厂 | D9: 150000 | E9: 5000 | F9: 0 | G9: 0 | H9: truck_parts_maker
A10: 5 | B10: payday | C10: 现金流日
A11: 6 | B11: dream | C11: 戛纳电影节 | D11: 125000 | E11: 0 | F11: 0 | G11: 0 | H11: cannes_film_festival
A12: 7 | B12: business | C12: 收购金矿 | D12: 150000 | E12: 25000 | F12: 3 | G12: 0 | H12: buy_a_gold_mine
A13: 8 | B13: dream | C13: 蒙大拿湖畔钓鱼小屋 | D13: 100000 | E13: 0 | F13: 0 | G13: 0 | H13: private_fishing_cabin_on_a_montana_lake
A14: 9 | B14: tax | C14: 税务审计
A15: 10 | B15: dream | C15: 以你命名的公园 | D15: 225000 | E15: 0 | F15: 0 | G15: 0 | H15: park_named_after_you
A16: 11 | B16: business | C16: 炸鸡连锁店 | D16: 300000 | E16: 10000 | F16: 0 | G16: 0 | H16: chicken_franchise
A17: 12 | B17: dream | C17: 竞选市长 | D17: 125000 | E17: 0 | F17: 0 | G17: 0 | H17: run_for_mayor
A18: 13 | B18: business | C18: 美容院 | D18: 250000 | E18: 10000 | F18: 0 | G18: 0 | H18: beauty_salons
A19: 14 | B19: dream | C19: 支持信仰事业 | D19: 175000 | E19: 0 | F19: 0 | G19: 0 | H19: gift_of_faith
A20: 15 | B20: business | C20: 汽车维修店 | D20: 150000 | E20: 6000 | F20: 0 | G20: 0 | H20: auto_repair_shop
A21: 16 | B21: dream | C21: 阿尔卑斯直升机滑雪 | D21: 150000 | E21: 0 | F21: 0 | G21: 0 | H21: heli_ski_the_swiss_alps
A22: 17 | B22: business | C22: 俄罗斯石油项目 | D22: 300000 | E22: 75000 | F22: 4 | G22: 0 | H22: russian_oil_deal
A23: 18 | B23: dream | C23: 与总统共进晚餐 | D23: 100000 | E23: 0 | F23: 0 | G23: 0 | H23: dinner_with_the_president
A24: 19 | B24: business | C24: T 恤连锁店 | D24: 200000 | E24: 8000 | F24: 0 | G24: 0 | H24: t_shirt_stores
A25: 20 | B25: dream | C25: 癌症与艾滋病研究中心 | D25: 225000 | E25: 0 | F25: 0 | G25: 0 | H25: research_center_for_cancer_and_aids
A26: 21 | B26: payday | C26: 现金流日
A27: 22 | B27: dream | C27: 游览世界七大奇迹 | D27: 200000 | E27: 0 | F27: 0 | G27: 0 | H27: 7_wonders_of_the_world
A28: 23 | B28: business | C28: 软件公司上市 | D28: 25000 | E28: 0 | F28: 6 | G28: 500000 | H28: software_co._ipo
A29: 24 | B29: dream | C29: 保护海洋哺乳动物 | D29: 125000 | E29: 0 | F29: 0 | G29: 0 | H29: save_the_ocean_mammals
A30: 25 | B30: divorce | C30: 离婚
A31: 26 | B31: dream | C31: 私人飞机旅行 | D31: 250000 | E31: 0 | F31: 0 | G31: 0 | H31: be_a__jet_setter_
A32: 27 | B32: business | C32: 60 户公寓楼 | D32: 300000 | E32: 8000 | F32: 0 | G32: 0 | H32: 60_unit_apartment_building
A33: 28 | B33: dream | C33: 环球高尔夫之旅 | D33: 150000 | E33: 0 | F33: 0 | G33: 0 | H33: golf_around_the_world
A34: 29 | B34: business | C34: 披萨连锁店 | D34: 225000 | E34: 7000 | F34: 0 | G34: 0 | H34: pizza_franchise
A35: 30 | B35: dream | C35: 儿童图书馆 | D35: 175000 | E35: 0 | F35: 0 | G35: 0 | H35: a_kids_library
A36: 31 | B36: business | C36: 200 间迷你仓库 | D36: 200000 | E36: 6000 | F36: 0 | G36: 0 | H36: 200_unit_mini_storage
A37: 32 | B37: dream | C37: 南太平洋海岛假期 | D37: 100000 | E37: 0 | F37: 0 | G37: 0 | H37: south_sea_island_fantasy
A38: 33 | B38: business | C38: 生物科技公司上市 | D38: 50000 | E38: 0 | F38: 5 | G38: 500000 | H38: bio_tech_co._ipo
A39: 34 | B39: dream | C39: 创业者和平服务团 | D39: 200000 | E39: 0 | F39: 0 | G39: 0 | H39: capitalists_peace_corps
A40: 35 | B40: business | C40: 干洗店 | D40: 100000 | E40: 3000 | F40: 0 | G40: 0 | H40: dry_cleaner
...

Sheet 数量复核
A1: 需求规则与数值主表
A2: 基线 v0.6.4 | 2026-10-27 | 自动化通过不代替最终验收
A3: 请使用筛选定位ID；字段名称保留实现含义，来源与状态不得删除。
A4: 组件 | B4: 实际条数 | C4: 来源 | D4: 工作簿条数公式 | E4: 比对结果
A5: jobs | B5: 12 | C5: reference-data.js | D5: =COUNTA(职业数据!A5:A1000) -> 12 | E5: =IF(B5=D5,"PASS","CHECK") -> PASS
A6: small | B6: 55 | C6: reference-data.js | D6: =COUNTA(小买卖!A5:A1000) -> 55 | E6: =IF(B6=D6,"PASS","CHECK") -> PASS
A7: big | B7: 40 | C7: reference-data.js | D7: =COUNTA(大买卖!A5:A1000) -> 40 | E7: =IF(B7=D7,"PASS","CHECK") -> PASS
A8: market | B8: 45 | C8: reference-data.js | D8: =COUNTA(市场!A5:A1000) -> 45 | E8: =IF(B8=D8,"PASS","CHECK") -> PASS
A9: doodads | B9: 42 | C9: reference-data.js | D9: =COUNTA(额外支出!A5:A1000) -> 42 | E9: =IF(B9=D9,"PASS","CHECK") -> PASS
A10: dreams | B10: 23 | C10: reference-data.js | D10: =COUNTA(梦想!A5:A1000) -> 23 | E10: =IF(B10=D10,"PASS","CHECK") -> PASS
A11: fast | B11: 48 | C11: reference-data.js | D11: =COUNTA(快车道!A5:A1000) -> 48 | E11: =IF(B11=D11,"PASS","CHECK") -> PASS

Sheet 机制数据字典
A1: 机制数据字典｜当前字段逐项映射
A2: 原始字段保留；金额与倍率按上下文区分，不能把所有amount都标为美元。
A3: 本表由实际数据记录遍历生成，规则解释按engine.js分支复核。
A4: 数据域 | B4: 字段 | C4: 中文含义 | D4: 实际类型 | E4: 单位／约束 | F4: 例值
A5: jobs | B5: id | C5: 职业标识 | D5: int | E5: 字符串／匹配与显示标识 | F5: 0
A6: jobs | B6: name | C6: 显示名 | D6: str | E6: 字符串／匹配与显示标识 | F6: 教师
A7: jobs | B7: english | C7: 原英文名 | D7: str | E7: 字符串／匹配与显示标识 | F7: Teacher (K-12)
A8: jobs | B8: salary | C8: 工资 | D8: int | E8: 金额／月（内圈） | F8: 3300
A9: jobs | B9: tax | C9: 税 | D9: int | E9: 金额／月（内圈） | F9: 630
A10: jobs | B10: homePayment | C10: home贷款月供 | D10: int | E10: 金额／月 | F10: 500
A11: jobs | B11: schoolPayment | C11: school贷款月供 | D11: int | E11: 金额／月 | F11: 60
A12: jobs | B12: carPayment | C12: car贷款月供 | D12: int | E12: 金额／月 | F12: 100
A13: jobs | B13: creditPayment | C13: credit贷款月供 | D13: int | E13: 金额／月 | F13: 90
A14: jobs | B14: retailPayment | C14: retail贷款月供 | D14: int | E14: 金额／月 | F14: 50
A15: jobs | B15: other | C15: 其他生活支出 | D15: int | E15: 金额／月（内圈） | F15: 760
A16: jobs | B16: savings | C16: 一次性储蓄 | D16: int | E16: 金额；price/range为每份，savings仅开局一次 | F16: 400
A17: jobs | B17: childCost | C17: 每孩月支出 | D17: int | E17: 金额／月（内圈） | F17: 180
A18: jobs | B18: homeDebt | C18: home贷款余额 | D18: int | E18: 金额；参考profile初始化school债务另见DEC-04 | F18: 50000
A19: jobs | B19: schoolDebt | C19: school贷款余额 | D19: int | E19: 金额；参考profile初始化school债务另见DEC-04 | F19: 12000
... A22: jobs | B22: retailDebt | C22: retail贷款余额 | D22: int | E22: 金额；参考profile初始化school债务另见DEC-04 | F22: 1000
A23: small | B23: sourceId | C23: 来源记录ID | D23: str | E23: 字符串／匹配与显示标识 | F23: small.0
A24: small | B24: anyoneBuy | C24: 共享报价可买入 | D24: bool | E24: 布尔标记；不是在线座位权限 | F24: true
A25: small | B25: name | C25: 显示名 | D25: str | E25: 字符串／匹配与显示标识 | F25: 银行存单
A26: small | B26: key | C26: 资产匹配键／特定模式增量 | D26: str | E26: 字符串／匹配与显示标识 | F26: CD
A27: small | B27: type | C27: 牌／格类型 | D27: str | E27: 字符串／匹配与显示标识 | F27: stock
A28: small | B28: units | C28: 单位／套数 | D28: int | E28: 计数；匹配时结合资产key和单位类型 | F28: 1
A29: small | B29: symbol | C29: 证券代码 | D29: str | E29: 字符串／匹配与显示标识 | F29: CD
A30: small | B30: price | C30: 每份报价 | D30: int | E30: 金额；price/range为每份，savings仅开局一次 | F30: 4000
A31: small | B31: dividend | C31: 每份净收入 | D31: int | E31: 金额／月（内圈） | F31: 20
A32: small | B32: rangeMin | C32: 常见报价下界 | D32: int | E32: 金额；price/range为每份，savings仅开局一次 | F32: 4000
A33: small | B33: rangeMax | C33: 常见报价上界 | D33: int | E33: 金额；price/range为每份，savings仅开局一次 | F33: 4000
A34: small | B34: down | C34: 首付 | D34: int | E34: 金额；price/range为每份，savings仅开局一次 | F34: 3000
A35: small | B35: value | C35: 资产总价 | D35: int | E35: 金额；price/range为每份，savings仅开局一次 | F35: 3000
A36: small | B36: debt | C36: 附带抵押贷款 | D36: int | E36: 金额；price/range为每份，savings仅开局一次 | F36: 0
A37: small | B37: income | C37: 净现金流 | D37: int | E37: 金额／月（内圈资产）或金额／现金流日（快车道） | F37: 0
A38: small | B38: factor | C38: 拆并股倍率 | D38: float/int | E38: 无量纲倍率；拆股2或并股0.5 | F38: 2
A39: big | B39: sourceId | C39: 来源记录ID | D39: str | E39: 字符串／匹配与显示标识 | F39: big.0
A40: big | B40: anyoneBuy | C40: 共享报价可买入 | D40: bool | E40: 布尔标记；不是在线座位权限 | F40: false
A41: big | B41: name | C41: 显示名 | D41: str | E41: 字符串／匹配与显示标识 | F41: 有限合伙投资
A42: big | B42: key | C42: 资产匹配键／特定模式增量 | D42: str | E42: 字符串／匹配与显示标识 | F42: PARTNER
...

Sheet 数值不变量
A1: 数值不变量与检查前提
A2: 仅在没有同时发生升阶／其他强制效果时比较单次现金变化。
A3: 实现应使用独立例值验证，不能只重写实现公式。
A4: ID | B4: 情形 | C4: 应满足关系 | D4: 前提／测试依据
A5: INV-01 | B5: 证券买入 | C5: 现金减少price×q，持股增加q | D5: 合法整数份数；不足现金先走贷款，未确认不买入
A6: INV-02 | B6: 证券出售 | C6: 现金增加price×q，按便宜批次扣除成本 | D6: 持仓足够；分红按剩余数量重新计算
A7: INV-03 | B7: 银行借款 | C7: 现金和银行余额加1000n，月供加100n | D7: 参考profile内圈；单位和借款上限经校验
A8: INV-04 | B8: 债务偿还 | C8: 现金减少实际偿还额；余额／月供按类型减少 | D8: 非银行全额；银行金额舍入和现金上限
A9: INV-05 | B9: 月净流入 | C9: 工资＋资产收入−税−其他−月供−子女支出 | D9: 参考profile开局省略school债务兼容差异
A10: INV-06 | B10: 房产资产栏 | C10: 显示总价value，不把首付cost当总价 | D10: 清算所得使用所选规则的首付基准
A11: INV-07 | B11: 取消与查看 | C11: 未执行交易；草稿及卡片恢复 | D11: 取消、确认、关闭窗口与结束回合分别测试
